{
 "cells": [
  {
   "cell_type": "code",
   "execution_count": 1,
   "metadata": {},
   "outputs": [],
   "source": [
    "%load_ext autoreload\n",
    "%autoreload 2"
   ]
  },
  {
   "cell_type": "code",
   "execution_count": 2,
   "metadata": {},
   "outputs": [],
   "source": [
    "from py_files.Limericks import Limerick_Generate"
   ]
  },
  {
   "cell_type": "code",
   "execution_count": 10,
   "metadata": {},
   "outputs": [],
   "source": [
    "lg = Limerick_Generate()"
   ]
  },
  {
   "cell_type": "code",
   "execution_count": 11,
   "metadata": {},
   "outputs": [
    {
     "data": {
      "text/plain": [
       "('democrat', 'sat', 'admit', 'sit', 'cat')"
      ]
     },
     "execution_count": 11,
     "metadata": {},
     "output_type": "execute_result"
    }
   ],
   "source": [
    "lg.get_five_words('sat')"
   ]
  },
  {
   "cell_type": "code",
   "execution_count": 13,
   "metadata": {},
   "outputs": [
    {
     "name": "stdout",
     "output_type": "stream",
     "text": [
      "['DT', 'NN', 'IN', 'JJ', 'NNS', 'VBD']\n"
     ]
    },
    {
     "ename": "ValueError",
     "evalue": "The passed save_path is not a valid checkpoint: py_files/models/all_combined_back/.model.ckpt-120000",
     "output_type": "error",
     "traceback": [
      "\u001b[0;31m---------------------------------------------------------------------------\u001b[0m",
      "\u001b[0;31mValueError\u001b[0m                                Traceback (most recent call last)",
      "\u001b[0;32m<ipython-input-13-2794896b984e>\u001b[0m in \u001b[0;36m<module>\u001b[0;34m\u001b[0m\n\u001b[0;32m----> 1\u001b[0;31m \u001b[0mt\u001b[0m\u001b[0;34m,\u001b[0m \u001b[0mo\u001b[0m \u001b[0;34m=\u001b[0m \u001b[0mlg\u001b[0m\u001b[0;34m.\u001b[0m\u001b[0mgen_line\u001b[0m\u001b[0;34m(\u001b[0m\u001b[0;34m'sat'\u001b[0m\u001b[0;34m,\u001b[0m \u001b[0mnum_sylls\u001b[0m\u001b[0;34m=\u001b[0m\u001b[0;36m7\u001b[0m\u001b[0;34m)\u001b[0m\u001b[0;34m\u001b[0m\u001b[0m\n\u001b[0m",
      "\u001b[0;32m~/projects/poetix/py_files/Limericks.py\u001b[0m in \u001b[0;36mgen_line\u001b[0;34m(self, w1, template, num_sylls)\u001b[0m\n\u001b[1;32m    325\u001b[0m             \u001b[0mckpt\u001b[0m \u001b[0;34m=\u001b[0m \u001b[0mtf\u001b[0m\u001b[0;34m.\u001b[0m\u001b[0mtrain\u001b[0m\u001b[0;34m.\u001b[0m\u001b[0mget_checkpoint_state\u001b[0m\u001b[0;34m(\u001b[0m\u001b[0mself\u001b[0m\u001b[0;34m.\u001b[0m\u001b[0mmodel_dir\u001b[0m\u001b[0;34m)\u001b[0m\u001b[0;34m\u001b[0m\u001b[0m\n\u001b[1;32m    326\u001b[0m             \u001b[0;32mif\u001b[0m \u001b[0mckpt\u001b[0m \u001b[0;32mand\u001b[0m \u001b[0mckpt\u001b[0m\u001b[0;34m.\u001b[0m\u001b[0mmodel_checkpoint_path\u001b[0m\u001b[0;34m:\u001b[0m\u001b[0;34m\u001b[0m\u001b[0m\n\u001b[0;32m--> 327\u001b[0;31m                 \u001b[0msaver\u001b[0m\u001b[0;34m.\u001b[0m\u001b[0mrestore\u001b[0m\u001b[0;34m(\u001b[0m\u001b[0msess\u001b[0m\u001b[0;34m,\u001b[0m \u001b[0mckpt\u001b[0m\u001b[0;34m.\u001b[0m\u001b[0mmodel_checkpoint_path\u001b[0m\u001b[0;34m)\u001b[0m\u001b[0;34m\u001b[0m\u001b[0m\n\u001b[0m\u001b[1;32m    328\u001b[0m                 \u001b[0mpoem\u001b[0m \u001b[0;34m=\u001b[0m \u001b[0;34m[\u001b[0m\u001b[0;34m]\u001b[0m\u001b[0;34m\u001b[0m\u001b[0m\n\u001b[1;32m    329\u001b[0m                 \u001b[0mline_num\u001b[0m \u001b[0;34m=\u001b[0m \u001b[0;36m0\u001b[0m\u001b[0;34m\u001b[0m\u001b[0m\n",
      "\u001b[0;32m~/.pyenv/versions/3.6.0/envs/poetix/lib/python3.6/site-packages/tensorflow/python/training/saver.py\u001b[0m in \u001b[0;36mrestore\u001b[0;34m(self, sess, save_path)\u001b[0m\n\u001b[1;32m   1536\u001b[0m     \u001b[0;32mif\u001b[0m \u001b[0;32mnot\u001b[0m \u001b[0mcheckpoint_management\u001b[0m\u001b[0;34m.\u001b[0m\u001b[0mcheckpoint_exists\u001b[0m\u001b[0;34m(\u001b[0m\u001b[0mcompat\u001b[0m\u001b[0;34m.\u001b[0m\u001b[0mas_text\u001b[0m\u001b[0;34m(\u001b[0m\u001b[0msave_path\u001b[0m\u001b[0;34m)\u001b[0m\u001b[0;34m)\u001b[0m\u001b[0;34m:\u001b[0m\u001b[0;34m\u001b[0m\u001b[0m\n\u001b[1;32m   1537\u001b[0m       raise ValueError(\"The passed save_path is not a valid checkpoint: \"\n\u001b[0;32m-> 1538\u001b[0;31m                        + compat.as_text(save_path))\n\u001b[0m\u001b[1;32m   1539\u001b[0m \u001b[0;34m\u001b[0m\u001b[0m\n\u001b[1;32m   1540\u001b[0m     \u001b[0mlogging\u001b[0m\u001b[0;34m.\u001b[0m\u001b[0minfo\u001b[0m\u001b[0;34m(\u001b[0m\u001b[0;34m\"Restoring parameters from %s\"\u001b[0m\u001b[0;34m,\u001b[0m \u001b[0mcompat\u001b[0m\u001b[0;34m.\u001b[0m\u001b[0mas_text\u001b[0m\u001b[0;34m(\u001b[0m\u001b[0msave_path\u001b[0m\u001b[0;34m)\u001b[0m\u001b[0;34m)\u001b[0m\u001b[0;34m\u001b[0m\u001b[0m\n",
      "\u001b[0;31mValueError\u001b[0m: The passed save_path is not a valid checkpoint: py_files/models/all_combined_back/.model.ckpt-120000"
     ]
    }
   ],
   "source": [
    "t, o = lg.gen_line('sat', num_sylls=7)"
   ]
  },
  {
   "cell_type": "code",
   "execution_count": null,
   "metadata": {},
   "outputs": [],
   "source": []
  }
 ],
 "metadata": {
  "kernelspec": {
   "display_name": "Python 3",
   "language": "python",
   "name": "python3"
  },
  "language_info": {
   "codemirror_mode": {
    "name": "ipython",
    "version": 3
   },
   "file_extension": ".py",
   "mimetype": "text/x-python",
   "name": "python",
   "nbconvert_exporter": "python",
   "pygments_lexer": "ipython3",
   "version": "3.6.0"
  }
 },
 "nbformat": 4,
 "nbformat_minor": 2
}
